2025-04-15 20:18:34,901 - create_tables - INFO - Initializing database connection...
2025-04-15 20:18:34,937 - create_tables - INFO - Dropping existing tables...
2025-04-15 20:18:35,004 - create_tables - ERROR - Error creating database tables: 'utf-8' codec can't decode byte 0xf3 in position 85: invalid continuation byte
2025-04-15 20:18:35,004 - create_tables - ERROR - 'utf-8' codec can't decode byte 0xf3 in position 85: invalid continuation byte
Traceback (most recent call last):
  File "D:\Personal\Code\AWR\create_db_tables.py", line 38, in create_tables
    Base.metadata.drop_all(db.engine)
    ~~~~~~~~~~~~~~~~~~~~~~^^^^^^^^^^^
  File "C:\Users\vhvaz\AppData\Roaming\Python\Python313\site-packages\sqlalchemy\sql\schema.py", line 5953, in drop_all
    bind._run_ddl_visitor(
    ~~~~~~~~~~~~~~~~~~~~~^
        ddl.SchemaDropper, self, checkfirst=checkfirst, tables=tables
        ^^^^^^^^^^^^^^^^^^^^^^^^^^^^^^^^^^^^^^^^^^^^^^^^^^^^^^^^^^^^^
    )
    ^
  File "C:\Users\vhvaz\AppData\Roaming\Python\Python313\site-packages\sqlalchemy\engine\base.py", line 3248, in _run_ddl_visitor
    with self.begin() as conn:
         ~~~~~~~~~~^^
  File "C:\Python313\Lib\contextlib.py", line 141, in __enter__
    return next(self.gen)
  File "C:\Users\vhvaz\AppData\Roaming\Python\Python313\site-packages\sqlalchemy\engine\base.py", line 3238, in begin
    with self.connect() as conn:
         ~~~~~~~~~~~~^^
  File "C:\Users\vhvaz\AppData\Roaming\Python\Python313\site-packages\sqlalchemy\engine\base.py", line 3274, in connect
    return self._connection_cls(self)
           ~~~~~~~~~~~~~~~~~~~~^^^^^^
  File "C:\Users\vhvaz\AppData\Roaming\Python\Python313\site-packages\sqlalchemy\engine\base.py", line 146, in __init__
    self._dbapi_connection = engine.raw_connection()
                             ~~~~~~~~~~~~~~~~~~~~~^^
  File "C:\Users\vhvaz\AppData\Roaming\Python\Python313\site-packages\sqlalchemy\engine\base.py", line 3298, in raw_connection
    return self.pool.connect()
           ~~~~~~~~~~~~~~~~~^^
  File "C:\Users\vhvaz\AppData\Roaming\Python\Python313\site-packages\sqlalchemy\pool\base.py", line 449, in connect
    return _ConnectionFairy._checkout(self)
           ~~~~~~~~~~~~~~~~~~~~~~~~~~^^^^^^
  File "C:\Users\vhvaz\AppData\Roaming\Python\Python313\site-packages\sqlalchemy\pool\base.py", line 1264, in _checkout
    fairy = _ConnectionRecord.checkout(pool)
  File "C:\Users\vhvaz\AppData\Roaming\Python\Python313\site-packages\sqlalchemy\pool\base.py", line 713, in checkout
    rec = pool._do_get()
  File "C:\Users\vhvaz\AppData\Roaming\Python\Python313\site-packages\sqlalchemy\pool\impl.py", line 179, in _do_get
    with util.safe_reraise():
         ~~~~~~~~~~~~~~~~~^^
  File "C:\Users\vhvaz\AppData\Roaming\Python\Python313\site-packages\sqlalchemy\util\langhelpers.py", line 146, in __exit__
    raise exc_value.with_traceback(exc_tb)
  File "C:\Users\vhvaz\AppData\Roaming\Python\Python313\site-packages\sqlalchemy\pool\impl.py", line 177, in _do_get
    return self._create_connection()
           ~~~~~~~~~~~~~~~~~~~~~~~^^
  File "C:\Users\vhvaz\AppData\Roaming\Python\Python313\site-packages\sqlalchemy\pool\base.py", line 390, in _create_connection
    return _ConnectionRecord(self)
  File "C:\Users\vhvaz\AppData\Roaming\Python\Python313\site-packages\sqlalchemy\pool\base.py", line 675, in __init__
    self.__connect()
    ~~~~~~~~~~~~~~^^
  File "C:\Users\vhvaz\AppData\Roaming\Python\Python313\site-packages\sqlalchemy\pool\base.py", line 901, in __connect
    with util.safe_reraise():
         ~~~~~~~~~~~~~~~~~^^
  File "C:\Users\vhvaz\AppData\Roaming\Python\Python313\site-packages\sqlalchemy\util\langhelpers.py", line 146, in __exit__
    raise exc_value.with_traceback(exc_tb)
  File "C:\Users\vhvaz\AppData\Roaming\Python\Python313\site-packages\sqlalchemy\pool\base.py", line 897, in __connect
    self.dbapi_connection = connection = pool._invoke_creator(self)
                                         ~~~~~~~~~~~~~~~~~~~~^^^^^^
  File "C:\Users\vhvaz\AppData\Roaming\Python\Python313\site-packages\sqlalchemy\engine\create.py", line 646, in connect
    return dialect.connect(*cargs, **cparams)
           ~~~~~~~~~~~~~~~^^^^^^^^^^^^^^^^^^^
  File "C:\Users\vhvaz\AppData\Roaming\Python\Python313\site-packages\sqlalchemy\engine\default.py", line 625, in connect
    return self.loaded_dbapi.connect(*cargs, **cparams)  # type: ignore[no-any-return]  # NOQA: E501
           ~~~~~~~~~~~~~~~~~~~~~~~~~^^^^^^^^^^^^^^^^^^^
  File "C:\Users\vhvaz\AppData\Roaming\Python\Python313\site-packages\psycopg2\__init__.py", line 135, in connect
    conn = _connect(dsn, connection_factory=connection_factory, **kwasync)
UnicodeDecodeError: 'utf-8' codec can't decode byte 0xf3 in position 85: invalid continuation byte
2025-04-15 20:34:36,319 - create_tables - INFO - Initializing database connection...
2025-04-15 20:34:36,355 - create_tables - INFO - Dropping existing tables...
2025-04-15 20:34:36,419 - create_tables - ERROR - Error creating database tables: 'utf-8' codec can't decode byte 0xf3 in position 85: invalid continuation byte
2025-04-15 20:34:36,419 - create_tables - ERROR - 'utf-8' codec can't decode byte 0xf3 in position 85: invalid continuation byte
Traceback (most recent call last):
  File "D:\Personal\Code\AWR\create_db_tables.py", line 38, in create_tables
    Base.metadata.drop_all(db.engine)
    ~~~~~~~~~~~~~~~~~~~~~~^^^^^^^^^^^
  File "C:\Users\vhvaz\AppData\Roaming\Python\Python313\site-packages\sqlalchemy\sql\schema.py", line 5953, in drop_all
    bind._run_ddl_visitor(
    ~~~~~~~~~~~~~~~~~~~~~^
        ddl.SchemaDropper, self, checkfirst=checkfirst, tables=tables
        ^^^^^^^^^^^^^^^^^^^^^^^^^^^^^^^^^^^^^^^^^^^^^^^^^^^^^^^^^^^^^
    )
    ^
  File "C:\Users\vhvaz\AppData\Roaming\Python\Python313\site-packages\sqlalchemy\engine\base.py", line 3248, in _run_ddl_visitor
    with self.begin() as conn:
         ~~~~~~~~~~^^
  File "C:\Python313\Lib\contextlib.py", line 141, in __enter__
    return next(self.gen)
  File "C:\Users\vhvaz\AppData\Roaming\Python\Python313\site-packages\sqlalchemy\engine\base.py", line 3238, in begin
    with self.connect() as conn:
         ~~~~~~~~~~~~^^
  File "C:\Users\vhvaz\AppData\Roaming\Python\Python313\site-packages\sqlalchemy\engine\base.py", line 3274, in connect
    return self._connection_cls(self)
           ~~~~~~~~~~~~~~~~~~~~^^^^^^
  File "C:\Users\vhvaz\AppData\Roaming\Python\Python313\site-packages\sqlalchemy\engine\base.py", line 146, in __init__
    self._dbapi_connection = engine.raw_connection()
                             ~~~~~~~~~~~~~~~~~~~~~^^
  File "C:\Users\vhvaz\AppData\Roaming\Python\Python313\site-packages\sqlalchemy\engine\base.py", line 3298, in raw_connection
    return self.pool.connect()
           ~~~~~~~~~~~~~~~~~^^
  File "C:\Users\vhvaz\AppData\Roaming\Python\Python313\site-packages\sqlalchemy\pool\base.py", line 449, in connect
    return _ConnectionFairy._checkout(self)
           ~~~~~~~~~~~~~~~~~~~~~~~~~~^^^^^^
  File "C:\Users\vhvaz\AppData\Roaming\Python\Python313\site-packages\sqlalchemy\pool\base.py", line 1264, in _checkout
    fairy = _ConnectionRecord.checkout(pool)
  File "C:\Users\vhvaz\AppData\Roaming\Python\Python313\site-packages\sqlalchemy\pool\base.py", line 713, in checkout
    rec = pool._do_get()
  File "C:\Users\vhvaz\AppData\Roaming\Python\Python313\site-packages\sqlalchemy\pool\impl.py", line 179, in _do_get
    with util.safe_reraise():
         ~~~~~~~~~~~~~~~~~^^
  File "C:\Users\vhvaz\AppData\Roaming\Python\Python313\site-packages\sqlalchemy\util\langhelpers.py", line 146, in __exit__
    raise exc_value.with_traceback(exc_tb)
  File "C:\Users\vhvaz\AppData\Roaming\Python\Python313\site-packages\sqlalchemy\pool\impl.py", line 177, in _do_get
    return self._create_connection()
           ~~~~~~~~~~~~~~~~~~~~~~~^^
  File "C:\Users\vhvaz\AppData\Roaming\Python\Python313\site-packages\sqlalchemy\pool\base.py", line 390, in _create_connection
    return _ConnectionRecord(self)
  File "C:\Users\vhvaz\AppData\Roaming\Python\Python313\site-packages\sqlalchemy\pool\base.py", line 675, in __init__
    self.__connect()
    ~~~~~~~~~~~~~~^^
  File "C:\Users\vhvaz\AppData\Roaming\Python\Python313\site-packages\sqlalchemy\pool\base.py", line 901, in __connect
    with util.safe_reraise():
         ~~~~~~~~~~~~~~~~~^^
  File "C:\Users\vhvaz\AppData\Roaming\Python\Python313\site-packages\sqlalchemy\util\langhelpers.py", line 146, in __exit__
    raise exc_value.with_traceback(exc_tb)
  File "C:\Users\vhvaz\AppData\Roaming\Python\Python313\site-packages\sqlalchemy\pool\base.py", line 897, in __connect
    self.dbapi_connection = connection = pool._invoke_creator(self)
                                         ~~~~~~~~~~~~~~~~~~~~^^^^^^
  File "C:\Users\vhvaz\AppData\Roaming\Python\Python313\site-packages\sqlalchemy\engine\create.py", line 646, in connect
    return dialect.connect(*cargs, **cparams)
           ~~~~~~~~~~~~~~~^^^^^^^^^^^^^^^^^^^
  File "C:\Users\vhvaz\AppData\Roaming\Python\Python313\site-packages\sqlalchemy\engine\default.py", line 625, in connect
    return self.loaded_dbapi.connect(*cargs, **cparams)  # type: ignore[no-any-return]  # NOQA: E501
           ~~~~~~~~~~~~~~~~~~~~~~~~~^^^^^^^^^^^^^^^^^^^
  File "C:\Users\vhvaz\AppData\Roaming\Python\Python313\site-packages\psycopg2\__init__.py", line 135, in connect
    conn = _connect(dsn, connection_factory=connection_factory, **kwasync)
UnicodeDecodeError: 'utf-8' codec can't decode byte 0xf3 in position 85: invalid continuation byte
2025-04-15 20:35:15,210 - create_tables - INFO - Initializing database connection...
2025-04-15 20:35:15,241 - create_tables - INFO - Dropping existing tables...
2025-04-15 20:35:15,302 - create_tables - ERROR - Error creating database tables: 'utf-8' codec can't decode byte 0xf3 in position 85: invalid continuation byte
2025-04-15 20:35:15,302 - create_tables - ERROR - 'utf-8' codec can't decode byte 0xf3 in position 85: invalid continuation byte
Traceback (most recent call last):
  File "D:\Personal\Code\AWR\create_db_tables.py", line 38, in create_tables
    Base.metadata.drop_all(db.engine)
    ~~~~~~~~~~~~~~~~~~~~~~^^^^^^^^^^^
  File "C:\Users\vhvaz\AppData\Roaming\Python\Python313\site-packages\sqlalchemy\sql\schema.py", line 5953, in drop_all
    bind._run_ddl_visitor(
    ~~~~~~~~~~~~~~~~~~~~~^
        ddl.SchemaDropper, self, checkfirst=checkfirst, tables=tables
        ^^^^^^^^^^^^^^^^^^^^^^^^^^^^^^^^^^^^^^^^^^^^^^^^^^^^^^^^^^^^^
    )
    ^
  File "C:\Users\vhvaz\AppData\Roaming\Python\Python313\site-packages\sqlalchemy\engine\base.py", line 3248, in _run_ddl_visitor
    with self.begin() as conn:
         ~~~~~~~~~~^^
  File "C:\Python313\Lib\contextlib.py", line 141, in __enter__
    return next(self.gen)
  File "C:\Users\vhvaz\AppData\Roaming\Python\Python313\site-packages\sqlalchemy\engine\base.py", line 3238, in begin
    with self.connect() as conn:
         ~~~~~~~~~~~~^^
  File "C:\Users\vhvaz\AppData\Roaming\Python\Python313\site-packages\sqlalchemy\engine\base.py", line 3274, in connect
    return self._connection_cls(self)
           ~~~~~~~~~~~~~~~~~~~~^^^^^^
  File "C:\Users\vhvaz\AppData\Roaming\Python\Python313\site-packages\sqlalchemy\engine\base.py", line 146, in __init__
    self._dbapi_connection = engine.raw_connection()
                             ~~~~~~~~~~~~~~~~~~~~~^^
  File "C:\Users\vhvaz\AppData\Roaming\Python\Python313\site-packages\sqlalchemy\engine\base.py", line 3298, in raw_connection
    return self.pool.connect()
           ~~~~~~~~~~~~~~~~~^^
  File "C:\Users\vhvaz\AppData\Roaming\Python\Python313\site-packages\sqlalchemy\pool\base.py", line 449, in connect
    return _ConnectionFairy._checkout(self)
           ~~~~~~~~~~~~~~~~~~~~~~~~~~^^^^^^
  File "C:\Users\vhvaz\AppData\Roaming\Python\Python313\site-packages\sqlalchemy\pool\base.py", line 1264, in _checkout
    fairy = _ConnectionRecord.checkout(pool)
  File "C:\Users\vhvaz\AppData\Roaming\Python\Python313\site-packages\sqlalchemy\pool\base.py", line 713, in checkout
    rec = pool._do_get()
  File "C:\Users\vhvaz\AppData\Roaming\Python\Python313\site-packages\sqlalchemy\pool\impl.py", line 179, in _do_get
    with util.safe_reraise():
         ~~~~~~~~~~~~~~~~~^^
  File "C:\Users\vhvaz\AppData\Roaming\Python\Python313\site-packages\sqlalchemy\util\langhelpers.py", line 146, in __exit__
    raise exc_value.with_traceback(exc_tb)
  File "C:\Users\vhvaz\AppData\Roaming\Python\Python313\site-packages\sqlalchemy\pool\impl.py", line 177, in _do_get
    return self._create_connection()
           ~~~~~~~~~~~~~~~~~~~~~~~^^
  File "C:\Users\vhvaz\AppData\Roaming\Python\Python313\site-packages\sqlalchemy\pool\base.py", line 390, in _create_connection
    return _ConnectionRecord(self)
  File "C:\Users\vhvaz\AppData\Roaming\Python\Python313\site-packages\sqlalchemy\pool\base.py", line 675, in __init__
    self.__connect()
    ~~~~~~~~~~~~~~^^
  File "C:\Users\vhvaz\AppData\Roaming\Python\Python313\site-packages\sqlalchemy\pool\base.py", line 901, in __connect
    with util.safe_reraise():
         ~~~~~~~~~~~~~~~~~^^
  File "C:\Users\vhvaz\AppData\Roaming\Python\Python313\site-packages\sqlalchemy\util\langhelpers.py", line 146, in __exit__
    raise exc_value.with_traceback(exc_tb)
  File "C:\Users\vhvaz\AppData\Roaming\Python\Python313\site-packages\sqlalchemy\pool\base.py", line 897, in __connect
    self.dbapi_connection = connection = pool._invoke_creator(self)
                                         ~~~~~~~~~~~~~~~~~~~~^^^^^^
  File "C:\Users\vhvaz\AppData\Roaming\Python\Python313\site-packages\sqlalchemy\engine\create.py", line 646, in connect
    return dialect.connect(*cargs, **cparams)
           ~~~~~~~~~~~~~~~^^^^^^^^^^^^^^^^^^^
  File "C:\Users\vhvaz\AppData\Roaming\Python\Python313\site-packages\sqlalchemy\engine\default.py", line 625, in connect
    return self.loaded_dbapi.connect(*cargs, **cparams)  # type: ignore[no-any-return]  # NOQA: E501
           ~~~~~~~~~~~~~~~~~~~~~~~~~^^^^^^^^^^^^^^^^^^^
  File "C:\Users\vhvaz\AppData\Roaming\Python\Python313\site-packages\psycopg2\__init__.py", line 135, in connect
    conn = _connect(dsn, connection_factory=connection_factory, **kwasync)
UnicodeDecodeError: 'utf-8' codec can't decode byte 0xf3 in position 85: invalid continuation byte
2025-04-15 20:35:18,371 - create_tables - INFO - Initializing database connection...
2025-04-15 20:35:18,402 - create_tables - INFO - Creating database tables...
2025-04-15 20:35:18,460 - create_tables - ERROR - Error creating database tables: 'utf-8' codec can't decode byte 0xf3 in position 85: invalid continuation byte
2025-04-15 20:35:18,460 - create_tables - ERROR - 'utf-8' codec can't decode byte 0xf3 in position 85: invalid continuation byte
Traceback (most recent call last):
  File "D:\Personal\Code\AWR\create_db_tables.py", line 42, in create_tables
    Base.metadata.create_all(db.engine)
    ~~~~~~~~~~~~~~~~~~~~~~~~^^^^^^^^^^^
  File "C:\Users\vhvaz\AppData\Roaming\Python\Python313\site-packages\sqlalchemy\sql\schema.py", line 5925, in create_all
    bind._run_ddl_visitor(
    ~~~~~~~~~~~~~~~~~~~~~^
        ddl.SchemaGenerator, self, checkfirst=checkfirst, tables=tables
        ^^^^^^^^^^^^^^^^^^^^^^^^^^^^^^^^^^^^^^^^^^^^^^^^^^^^^^^^^^^^^^^
    )
    ^
  File "C:\Users\vhvaz\AppData\Roaming\Python\Python313\site-packages\sqlalchemy\engine\base.py", line 3248, in _run_ddl_visitor
    with self.begin() as conn:
         ~~~~~~~~~~^^
  File "C:\Python313\Lib\contextlib.py", line 141, in __enter__
    return next(self.gen)
  File "C:\Users\vhvaz\AppData\Roaming\Python\Python313\site-packages\sqlalchemy\engine\base.py", line 3238, in begin
    with self.connect() as conn:
         ~~~~~~~~~~~~^^
  File "C:\Users\vhvaz\AppData\Roaming\Python\Python313\site-packages\sqlalchemy\engine\base.py", line 3274, in connect
    return self._connection_cls(self)
           ~~~~~~~~~~~~~~~~~~~~^^^^^^
  File "C:\Users\vhvaz\AppData\Roaming\Python\Python313\site-packages\sqlalchemy\engine\base.py", line 146, in __init__
    self._dbapi_connection = engine.raw_connection()
                             ~~~~~~~~~~~~~~~~~~~~~^^
  File "C:\Users\vhvaz\AppData\Roaming\Python\Python313\site-packages\sqlalchemy\engine\base.py", line 3298, in raw_connection
    return self.pool.connect()
           ~~~~~~~~~~~~~~~~~^^
  File "C:\Users\vhvaz\AppData\Roaming\Python\Python313\site-packages\sqlalchemy\pool\base.py", line 449, in connect
    return _ConnectionFairy._checkout(self)
           ~~~~~~~~~~~~~~~~~~~~~~~~~~^^^^^^
  File "C:\Users\vhvaz\AppData\Roaming\Python\Python313\site-packages\sqlalchemy\pool\base.py", line 1264, in _checkout
    fairy = _ConnectionRecord.checkout(pool)
  File "C:\Users\vhvaz\AppData\Roaming\Python\Python313\site-packages\sqlalchemy\pool\base.py", line 713, in checkout
    rec = pool._do_get()
  File "C:\Users\vhvaz\AppData\Roaming\Python\Python313\site-packages\sqlalchemy\pool\impl.py", line 179, in _do_get
    with util.safe_reraise():
         ~~~~~~~~~~~~~~~~~^^
  File "C:\Users\vhvaz\AppData\Roaming\Python\Python313\site-packages\sqlalchemy\util\langhelpers.py", line 146, in __exit__
    raise exc_value.with_traceback(exc_tb)
  File "C:\Users\vhvaz\AppData\Roaming\Python\Python313\site-packages\sqlalchemy\pool\impl.py", line 177, in _do_get
    return self._create_connection()
           ~~~~~~~~~~~~~~~~~~~~~~~^^
  File "C:\Users\vhvaz\AppData\Roaming\Python\Python313\site-packages\sqlalchemy\pool\base.py", line 390, in _create_connection
    return _ConnectionRecord(self)
  File "C:\Users\vhvaz\AppData\Roaming\Python\Python313\site-packages\sqlalchemy\pool\base.py", line 675, in __init__
    self.__connect()
    ~~~~~~~~~~~~~~^^
  File "C:\Users\vhvaz\AppData\Roaming\Python\Python313\site-packages\sqlalchemy\pool\base.py", line 901, in __connect
    with util.safe_reraise():
         ~~~~~~~~~~~~~~~~~^^
  File "C:\Users\vhvaz\AppData\Roaming\Python\Python313\site-packages\sqlalchemy\util\langhelpers.py", line 146, in __exit__
    raise exc_value.with_traceback(exc_tb)
  File "C:\Users\vhvaz\AppData\Roaming\Python\Python313\site-packages\sqlalchemy\pool\base.py", line 897, in __connect
    self.dbapi_connection = connection = pool._invoke_creator(self)
                                         ~~~~~~~~~~~~~~~~~~~~^^^^^^
  File "C:\Users\vhvaz\AppData\Roaming\Python\Python313\site-packages\sqlalchemy\engine\create.py", line 646, in connect
    return dialect.connect(*cargs, **cparams)
           ~~~~~~~~~~~~~~~^^^^^^^^^^^^^^^^^^^
  File "C:\Users\vhvaz\AppData\Roaming\Python\Python313\site-packages\sqlalchemy\engine\default.py", line 625, in connect
    return self.loaded_dbapi.connect(*cargs, **cparams)  # type: ignore[no-any-return]  # NOQA: E501
           ~~~~~~~~~~~~~~~~~~~~~~~~~^^^^^^^^^^^^^^^^^^^
  File "C:\Users\vhvaz\AppData\Roaming\Python\Python313\site-packages\psycopg2\__init__.py", line 135, in connect
    conn = _connect(dsn, connection_factory=connection_factory, **kwasync)
UnicodeDecodeError: 'utf-8' codec can't decode byte 0xf3 in position 85: invalid continuation byte
2025-04-15 20:35:22,373 - create_tables - INFO - Initializing database connection...
2025-04-15 20:35:22,407 - create_tables - INFO - Creating database tables...
2025-04-15 20:35:22,467 - create_tables - ERROR - Error creating database tables: 'utf-8' codec can't decode byte 0xf3 in position 85: invalid continuation byte
2025-04-15 20:35:22,467 - create_tables - ERROR - 'utf-8' codec can't decode byte 0xf3 in position 85: invalid continuation byte
Traceback (most recent call last):
  File "D:\Personal\Code\AWR\create_db_tables.py", line 42, in create_tables
    Base.metadata.create_all(db.engine)
    ~~~~~~~~~~~~~~~~~~~~~~~~^^^^^^^^^^^
  File "C:\Users\vhvaz\AppData\Roaming\Python\Python313\site-packages\sqlalchemy\sql\schema.py", line 5925, in create_all
    bind._run_ddl_visitor(
    ~~~~~~~~~~~~~~~~~~~~~^
        ddl.SchemaGenerator, self, checkfirst=checkfirst, tables=tables
        ^^^^^^^^^^^^^^^^^^^^^^^^^^^^^^^^^^^^^^^^^^^^^^^^^^^^^^^^^^^^^^^
    )
    ^
  File "C:\Users\vhvaz\AppData\Roaming\Python\Python313\site-packages\sqlalchemy\engine\base.py", line 3248, in _run_ddl_visitor
    with self.begin() as conn:
         ~~~~~~~~~~^^
  File "C:\Python313\Lib\contextlib.py", line 141, in __enter__
    return next(self.gen)
  File "C:\Users\vhvaz\AppData\Roaming\Python\Python313\site-packages\sqlalchemy\engine\base.py", line 3238, in begin
    with self.connect() as conn:
         ~~~~~~~~~~~~^^
  File "C:\Users\vhvaz\AppData\Roaming\Python\Python313\site-packages\sqlalchemy\engine\base.py", line 3274, in connect
    return self._connection_cls(self)
           ~~~~~~~~~~~~~~~~~~~~^^^^^^
  File "C:\Users\vhvaz\AppData\Roaming\Python\Python313\site-packages\sqlalchemy\engine\base.py", line 146, in __init__
    self._dbapi_connection = engine.raw_connection()
                             ~~~~~~~~~~~~~~~~~~~~~^^
  File "C:\Users\vhvaz\AppData\Roaming\Python\Python313\site-packages\sqlalchemy\engine\base.py", line 3298, in raw_connection
    return self.pool.connect()
           ~~~~~~~~~~~~~~~~~^^
  File "C:\Users\vhvaz\AppData\Roaming\Python\Python313\site-packages\sqlalchemy\pool\base.py", line 449, in connect
    return _ConnectionFairy._checkout(self)
           ~~~~~~~~~~~~~~~~~~~~~~~~~~^^^^^^
  File "C:\Users\vhvaz\AppData\Roaming\Python\Python313\site-packages\sqlalchemy\pool\base.py", line 1264, in _checkout
    fairy = _ConnectionRecord.checkout(pool)
  File "C:\Users\vhvaz\AppData\Roaming\Python\Python313\site-packages\sqlalchemy\pool\base.py", line 713, in checkout
    rec = pool._do_get()
  File "C:\Users\vhvaz\AppData\Roaming\Python\Python313\site-packages\sqlalchemy\pool\impl.py", line 179, in _do_get
    with util.safe_reraise():
         ~~~~~~~~~~~~~~~~~^^
  File "C:\Users\vhvaz\AppData\Roaming\Python\Python313\site-packages\sqlalchemy\util\langhelpers.py", line 146, in __exit__
    raise exc_value.with_traceback(exc_tb)
  File "C:\Users\vhvaz\AppData\Roaming\Python\Python313\site-packages\sqlalchemy\pool\impl.py", line 177, in _do_get
    return self._create_connection()
           ~~~~~~~~~~~~~~~~~~~~~~~^^
  File "C:\Users\vhvaz\AppData\Roaming\Python\Python313\site-packages\sqlalchemy\pool\base.py", line 390, in _create_connection
    return _ConnectionRecord(self)
  File "C:\Users\vhvaz\AppData\Roaming\Python\Python313\site-packages\sqlalchemy\pool\base.py", line 675, in __init__
    self.__connect()
    ~~~~~~~~~~~~~~^^
  File "C:\Users\vhvaz\AppData\Roaming\Python\Python313\site-packages\sqlalchemy\pool\base.py", line 901, in __connect
    with util.safe_reraise():
         ~~~~~~~~~~~~~~~~~^^
  File "C:\Users\vhvaz\AppData\Roaming\Python\Python313\site-packages\sqlalchemy\util\langhelpers.py", line 146, in __exit__
    raise exc_value.with_traceback(exc_tb)
  File "C:\Users\vhvaz\AppData\Roaming\Python\Python313\site-packages\sqlalchemy\pool\base.py", line 897, in __connect
    self.dbapi_connection = connection = pool._invoke_creator(self)
                                         ~~~~~~~~~~~~~~~~~~~~^^^^^^
  File "C:\Users\vhvaz\AppData\Roaming\Python\Python313\site-packages\sqlalchemy\engine\create.py", line 646, in connect
    return dialect.connect(*cargs, **cparams)
           ~~~~~~~~~~~~~~~^^^^^^^^^^^^^^^^^^^
  File "C:\Users\vhvaz\AppData\Roaming\Python\Python313\site-packages\sqlalchemy\engine\default.py", line 625, in connect
    return self.loaded_dbapi.connect(*cargs, **cparams)  # type: ignore[no-any-return]  # NOQA: E501
           ~~~~~~~~~~~~~~~~~~~~~~~~~^^^^^^^^^^^^^^^^^^^
  File "C:\Users\vhvaz\AppData\Roaming\Python\Python313\site-packages\psycopg2\__init__.py", line 135, in connect
    conn = _connect(dsn, connection_factory=connection_factory, **kwasync)
UnicodeDecodeError: 'utf-8' codec can't decode byte 0xf3 in position 85: invalid continuation byte
2025-04-15 20:36:44,167 - create_tables - INFO - Initializing database connection...
2025-04-15 20:36:44,200 - create_tables - INFO - Creating database tables...
2025-04-15 20:36:44,348 - create_tables - INFO - Database tables created successfully.
2025-04-15 20:36:58,047 - create_tables - INFO - Initializing database connection...
2025-04-15 20:36:58,092 - create_tables - INFO - Dropping existing tables...
2025-04-15 20:36:58,182 - create_tables - INFO - Existing tables dropped successfully.
2025-04-15 20:36:58,183 - create_tables - INFO - Creating database tables...
2025-04-15 20:36:58,252 - create_tables - INFO - Database tables created successfully.
2025-04-15 21:03:29,831 - create_tables - INFO - Initializing database connection...
2025-04-15 21:03:29,886 - create_tables - INFO - Dropping existing tables...
2025-04-15 21:03:29,978 - create_tables - INFO - Existing tables dropped successfully.
2025-04-15 21:03:29,979 - create_tables - INFO - Creating database tables...
2025-04-15 21:03:30,056 - create_tables - INFO - Database tables created successfully.
2025-04-15 21:26:46,440 - create_tables - INFO - Initializing database connection...
2025-04-15 21:26:46,474 - create_tables - INFO - Dropping existing tables...
2025-04-15 21:26:46,550 - create_tables - INFO - Existing tables dropped successfully.
2025-04-15 21:26:46,550 - create_tables - INFO - Creating database tables...
2025-04-15 21:26:46,619 - create_tables - INFO - Database tables created successfully.
2025-04-15 21:27:30,937 - create_tables - INFO - Initializing database connection...
2025-04-15 21:27:30,970 - create_tables - INFO - Dropping existing tables...
2025-04-15 21:27:31,055 - create_tables - INFO - Existing tables dropped successfully.
2025-04-15 21:27:31,056 - create_tables - INFO - Creating database tables...
2025-04-15 21:27:31,122 - create_tables - INFO - Database tables created successfully.
